Workbook

Sheet 비교
A1: Microduck 클론 — 다이나믹셀(오리지널·저렴) vs 일반 서보
A2: 범례: 노란 칸·파란 글씨 = 입력값. 각 버전 시트의 수량·단가(파란 글씨)도 수정 가능.
A4: 환율 (원/USD) | C4: 1400
A5: 예비 포함 (1=포함, 0=제외) | C5: 1
A7: 분류 | B7: 오리지널 | C7: 저렴한 버전 | D7: 일반 서보 버전
A8: 구동 | B8: =SUMIFS(오리지널!$J$6:$J$36,오리지널!$A$6:$A$36,A8) -> 498630 | C8: =SUMIFS('저렴한 버전'!$J$6:$J$26,'저렴한 버전'!$A$6:$A$26,A8) -> 372100 | D8: =SUMIFS('일반 서보 버전'!$J$6:$J$26,'일반 서보 버전'!$A$6:$A$26,A8) -> 101000
A9: 컴퓨팅 | B9: =SUMIFS(오리지널!$J$6:$J$36,오리지널!$A$6:$A$36,A9) -> 31000 | C9: =SUMIFS('저렴한 버전'!$J$6:$J$26,'저렴한 버전'!$A$6:$A$26,A9) -> 37000 | D9: =SUMIFS('일반 서보 버전'!$J$6:$J$26,'일반 서보 버전'!$A$6:$A$26,A9) -> 36300
A10: 센서 | B10: =SUMIFS(오리지널!$J$6:$J$36,오리지널!$A$6:$A$36,A10) -> 126642 | C10: =SUMIFS('저렴한 버전'!$J$6:$J$26,'저렴한 버전'!$A$6:$A$26,A10) -> 37356 | D10: =SUMIFS('일반 서보 버전'!$J$6:$J$26,'일반 서보 버전'!$A$6:$A$26,A10) -> 32000
A11: 오디오 | B11: =SUMIFS(오리지널!$J$6:$J$36,오리지널!$A$6:$A$36,A11) -> 7000 | C11: =SUMIFS('저렴한 버전'!$J$6:$J$26,'저렴한 버전'!$A$6:$A$26,A11) -> 0 | D11: =SUMIFS('일반 서보 버전'!$J$6:$J$26,'일반 서보 버전'!$A$6:$A$26,A11) -> 0
A12: 전원 | B12: =SUMIFS(오리지널!$J$6:$J$36,오리지널!$A$6:$A$36,A12) -> 60500 | C12: =SUMIFS('저렴한 버전'!$J$6:$J$26,'저렴한 버전'!$A$6:$A$26,A12) -> 33000 | D12: =SUMIFS('일반 서보 버전'!$J$6:$J$26,'일반 서보 버전'!$A$6:$A$26,A12) -> 50000
A13: 버스·PCB | B13: =SUMIFS(오리지널!$J$6:$J$36,오리지널!$A$6:$A$36,A13) -> 15230 | C13: =SUMIFS('저렴한 버전'!$J$6:$J$26,'저렴한 버전'!$A$6:$A$26,A13) -> 14810 | D13: =SUMIFS('일반 서보 버전'!$J$6:$J$26,'일반 서보 버전'!$A$6:$A$26,A13) -> 0
A14: 기구 | B14: =SUMIFS(오리지널!$J$6:$J$36,오리지널!$A$6:$A$36,A14) -> 69600 | C14: =SUMIFS('저렴한 버전'!$J$6:$J$26,'저렴한 버전'!$A$6:$A$26,A14) -> 33400 | D14: =SUMIFS('일반 서보 버전'!$J$6:$J$26,'일반 서보 버전'!$A$6:$A$26,A14) -> 14000
A15: 출력소재 | B15: =SUMIFS(오리지널!$J$6:$J$36,오리지널!$A$6:$A$36,A15) -> 33000 | C15: =SUMIFS('저렴한 버전'!$J$6:$J$26,'저렴한 버전'!$A$6:$A$26,A15) -> 33000 | D15: =SUMIFS('일반 서보 버전'!$J$6:$J$26,'일반 서보 버전'!$A$6:$A$26,A15) -> 33000
A16: 기타 | B16: =SUMIFS(오리지널!$J$6:$J$36,오리지널!$A$6:$A$36,A16) -> 55000 | C16: =SUMIFS('저렴한 버전'!$J$6:$J$26,'저렴한 버전'!$A$6:$A$26,A16) -> 0 | D16: =SUMIFS('일반 서보 버전'!$J$6:$J$26,'일반 서보 버전'!$A$6:$A$26,A16) -> 0
A17: 제어·배선 | B17: =SUMIFS(오리지널!$J$6:$J$36,오리지널!$A$6:$A$36,A17) -> 0 | C17: =SUMIFS('저렴한 버전'!$J$6:$J$26,'저렴한 버전'!$A$6:$A$26,A17) -> 0 | D17: =SUMIFS('일반 서보 버전'!$J$6:$J$26,'일반 서보 버전'!$A$6:$A$26,A17) -> 9000
A18: 합계 | B18: =오리지널!$J$38 -> 896602 | C18: ='저렴한 버전'!$J$28 -> 560666 | D18: ='일반 서보 버전'!$J$28 -> 275300
A19: 주력 서보 비용 (첫 행) | B19: =오리지널!$J$6 -> 422400 | C19: ='저렴한 버전'!$J$6 -> 369600 | D19: ='일반 서보 버전'!$J$6 -> 65000
A21: 항목 | B21: 오리지널 | C21: 저렴한 버전 | D21: 일반 서보 버전
A22: 서보 | B22: XL330 15개 + 예비 1 | C22: XL330 14개 (부리 고정) | D22: MG996R 11 + MG90S 4 (+예비)
A23: 크기·무게 | B23: 25 cm, 약 0.74 kg | C23: 25 cm, 약 0.74 kg | D23: 약 37 cm, 1.4–1.7 kg (추정)
A24: 위치 피드백 | B24: 서보 내장 | C24: 서보 내장 | D24: 가변저항 배선 개조 + ADS1115
A25: 제어기 | B25: Radxa Zero 3W + UART 버스 | C25: Radxa Zero 3W + UART 버스 | D25: Pi Zero 2W + PCA9685 (I²C)
A26: 센서 | B26: IMU + ToF + 카메라 | C26: IMU만 | D26: BNO085 IMU만
A27: 오디오·조종 | B27: 코덱·스피커·마이크, Xbox 패드 | C27: 없음, UDP 패드 | D27: 없음, UDP 패드
A28: CAD | B28: Pollen 형상 그대로 | C28: Pollen 형상 그대로 | D28: 1.5배 새로 설계
A29: 정책·런타임 | B29: Pollen 것 그대로 | C29: 부리 제외 패치 | D29: 새 액추에이터 모델로 재학습, 파이썬 런타임 새로 작성
A30: 난이도 | B30: 중 | C30: 중 | D30: 상 (sim2real 어려움)
A32: ⚠ 2026-10-29 기준 Radxa Zero 3W(다이나믹셀 버전)·Pi Zero 2W(일반 서보 버전) 모두 일부 판매처 품절.
A33: 가격근거 '확인' = 판매 페이지 정가 확인, '추정' = 시세 추정. 배송비 별도.

Sheet 오리지널
A1: Microduck 클론 BOM — 오리지널
A2: 다이나믹셀 · Pollen Microduck 하드웨어 그대로: 15축(부리 포함), ToF·카메라·오디오, U2D2, 게임패드, 예비 부품.
A3: 환율·예비 포함 여부는 '비교' 시트의 노란 칸에서 바꾼다. 쿠폰 할인·배송비 미반영.
A5: 분류 | B5: 품목 | C5: 규격/모델 | D5: 수량 | E5: 예비 | F5: 총수량 | G5: 단가 | H5: 통화 | I5: 단가(원) | J5: 합계(원) | K5: 가격근거 | L5: 구매처 | M5: 구매 링크 | N5: 링크유형 | O5: 대안 구매처 | P5: 메모
A6: 구동 | B6: 다이나믹셀 서보 | C6: ROBOTIS XL330-M288-T | D6: 15 | E6: 1 | F6: =D6+E6*비교!$C$5 -> 16 | G6: 26400 | H6: KRW | I6: =IF(H6="USD",G6*비교!$C$4,G6) -> 26400 | J6: =F6*I6 -> 422400 | K6: 확인 | L6: 로보티즈 공식몰 | M6: https://www.robotis.com/shop/item.php?it_id=902-0163-000 | N6: 상품 | O6: 로보몰(동일가, 품절): https://robomall.co.kr/product/%EB%8B%A4%EC%9D%B4%EB%82%98%EB%AF%B9%EC%85%80-xl330-m288-t/21150/ | P6: 준비기간 40일 → 가장 먼저 주문. 5만원 이상 무료배송. 저렴한 버전은 부리(ID 34) 생략 → 14개
A7: 구동 | B7: 서보 설정 인터페이스 | C7: ROBOTIS U2D2 | D7: 1 | E7: 0 | F7: =D7+E7*비교!$C$5 -> 1 | G7: 36300 | H7: KRW | I7: =IF(H7="USD",G7*비교!$C$4,G7) -> 36300 | J7: =F7*I7 -> 36300 | K7: 확인 | L7: 로보티즈 공식몰 | M7: https://www.robotis.com/shop/item.php?it_id=902-0132-000 | N7: 상품 | P7: 정품 USB 인터페이스. 준비기간 10일
A8: 구동 | B8: U2D2 전원 허브 | C8: U2D2 PHB Set | D8: 1 | E8: 0 | F8: =D8+E8*비교!$C$5 -> 1 | G8: 21780 | H8: KRW | I8: =IF(H8="USD",G8*비교!$C$4,G8) -> 21780 | J8: =F8*I8 -> 21780 | K8: 확인 | L8: 로보티즈 공식몰 | M8: https://www.robotis.com/shop/list.php?ca_id=202030 | N8: 목록 | P8: 벤치에서 서보 여러 개 전원 분배
A9: 구동 | B9: 서보 케이블 추가 | C9: 로봇 케이블-X3P 180mm 10개 | D9: 1 | E9: 0 | F9: =D9+E9*비교!$C$5 -> 1 | G9: 18150 | H9: KRW | I9: =IF(H9="USD",G9*비교!$C$4,G9) -> 18150 | J9: =F9*I9 -> 18150 | K9: 확인 | L9: 로보티즈 공식몰 | M9: https://www.robotis.com/shop/list.php?ca_id=202030 | N9: 목록 | O9: 자작: https://search.shopping.naver.com/search/all?query=JST+EH+3%ED%95%80+%EC%BC%80%EC%9D%B4%EB%B8%94&sort=price_asc | P9: 저렴한 버전은 서보 동봉 케이블(개당 1개)로 해결
A10: 컴퓨팅 | B10: 메인 SBC | C10: Radxa Zero 3W (1GB/8GB eMMC 또는 2GB/16GB) | D10: 1 | E10: 0 | F10: =D10+E10*비교!$C$5 -> 1 | G10: 20 | H10: USD | I10: =IF(H10="USD",G10*비교!$C$4,G10) -> 28000 | J10: =F10*I10 -> 28000 | K10: 확인 | L10: ARACE (Radxa 공식 파트너) | M10: https://arace.tech/products/radxa-zero-3w | N10: 상품 | O10: 알리: https://www.aliexpress.com/w/wholesale-Radxa-Zero-3W.html?SortType=price_asc / allnetchina: https://shop.allnetchina.cn/products/copy-of-radxa-zero-3w | P10: ⚠ 2026-10-29 확인 시 ARACE·ameridroid·allnetchina 전 모델 품절. 재입고 알림 신청. 대안: Orange Pi Zero 2W / Pi Zero 2W (같은 65×30, 런타임 포팅 필요)
A11: 컴퓨팅 | B11: 방열판 | C11: Radxa ZERO 3W/3E 전용 히트싱크 | D11: 1 | E11: 0 | F11: =D11+E11*비교!$C$5 -> 1 | G11: 3000 | H11: KRW | I11: =IF(H11="USD",G11*비교!$C$4,G11) -> 3000 | J11: =F11*I11 -> 3000 | K11: 추정 | L11: 알리익스프레스 | M11: https://www.aliexpress.us/item/3256806829446736.html | N11: 상품 | P11: 원본 문서에 95 °C 스로틀링 사례
A12: 센서 | B12: 몸통 IMU | C12: SparkFun 6DoF LSM6DSV16X (Qwiic) SEN-21325 | D12: 1 | E12: 1 | F12: =D12+E12*비교!$C$5 -> 2 | G12: 24.54 | H12: USD | I12: =IF(H12="USD",G12*비교!$C$4,G12) -> 34356 | J12: =F12*I12 -> 68712 | K12: 확인 | L12: SparkFun | M12: https://www.sparkfun.com/sparkfun-6dof-imu-breakout-lsm6dsv16x-qwiic.html | N12: 상품 | O12: 알리 저가 모듈: https://www.aliexpress.com/w/wholesale-LSM6DSV16X-module.html?SortType=price_asc | P12: 원본과 같은 칩. 알리 저가 모듈을 찾으면 저렴한 버전은 그쪽으로
A13: 센서 | B13: IMU 브리지 MCU | C13: ESP32-C3 SuperMini | D13: 1 | E13: 1 | F13: =D13+E13*비교!$C$5 -> 2 | G13: 3000 | H13: KRW | I13: =IF(H13="USD",G13*비교!$C$4,G13) -> 3000 | J13: =F13*I13 -> 6000 | K13: 추정 | L13: 네이버쇼핑 최저가 | M13: https://search.shopping.naver.com/search/all?query=ESP32-C3+SuperMini&sort=price_asc | N13: 검색 | O13: 알리: https://www.aliexpress.com/w/wholesale-ESP32-C3-SuperMini.html?SortType=price_asc | P13: 버스 ID 200 슬레이브 펌웨어 (firmware/imu_to_dxl)
A14: 센서 | B14: ToF 8×8 깊이센서 | C14: Pololu VL53L8CX Carrier #3419 | D14: 1 | E14: 0 | F14: =D14+E14*비교!$C$5 -> 1 | G14: 24.95 | H14: USD | I14: =IF(H14="USD",G14*비교!$C$4,G14) -> 34930 | J14: =F14*I14 -> 34930 | K14: 확인 | L14: DigiKey 코리아 | M14: https://www.digikey.kr/en/products/detail/pololu/3419/22310072 | N14: 상품 | O14: Pololu 직구: https://www.pololu.com/product/3419 | P14: 원본 머리 깊이센서 (VL53L8CX)
A15: 센서 | B15: 카메라 | C15: IMX219 모듈 + M12 광각렌즈 | D15: 1 | E15: 0 | F15: =D15+E15*비교!$C$5 -> 1 | G15: 15000 | H15: KRW | I15: =IF(H15="USD",G15*비교!$C$4,G15) -> 15000 | J15: =F15*I15 -> 15000 | K15: 추정 | L15: 알리익스프레스 | M15: https://www.aliexpress.com/w/wholesale-IMX219-M12-camera-module.html?SortType=price_asc | N15: 검색 | O15: 네이버: https://search.shopping.naver.com/search/all?query=IMX219+%EC%B9%B4%EB%A9%94%EB%9D%BC+%EB%AA%A8%EB%93%88&sort=price_asc | P15: Radxa Zero 3W는 22핀 CSI
A16: 센서 | B16: CSI 케이블 | C16: 22핀↔15핀 FPC 100 mm | D16: 1 | E16: 0 | F16: =D16+E16*비교!$C$5 -> 1 | G16: 2000 | H16: KRW | I16: =IF(H16="USD",G16*비교!$C$4,G16) -> 2000 | J16: =F16*I16 -> 2000 | K16: 추정 | L16: 알리익스프레스 | M16: https://www.aliexpress.com/w/wholesale-22pin-to-15pin-CSI-cable.html?SortType=price_asc | N16: 검색 | P16: 15핀 카메라 모듈일 때
A17: 오디오 | B17: 오디오 코덱 | C17: TLV320AIC3104IRHBR (HAT 실장) | D17: 1 | E17: 0 | F17: =D17+E17*비교!$C$5 -> 1 | G17: 2.5 | H17: USD | I17: =IF(H17="USD",G17*비교!$C$4,G17) -> 3500 | J17: =F17*I17 -> 3500 | K17: 추정 | L17: LCSC | M17: https://www.lcsc.com/search?q=TLV320AIC3104 | N17: 검색 | P17: 원본 런타임이 전제하는 코덱. HAT에 실장 (QFN 납땜 또는 JLCPCB 조립)
A18: 오디오 | B18: 스피커 | C18: 35×25×7 mm 8Ω 1W | D18: 1 | E18: 0 | F18: =D18+E18*비교!$C$5 -> 1 | G18: 1500 | H18: KRW | I18: =IF(H18="USD",G18*비교!$C$4,G18) -> 1500 | J18: =F18*I18 -> 1500 | K18: 추정 | L18: 네이버쇼핑 최저가 | M18: https://search.shopping.naver.com/search/all?query=%EC%86%8C%ED%98%95+%EC%8A%A4%ED%94%BC%EC%BB%A4+8%EC%98%B4+1W+3525&sort=price_asc | N18: 검색 | P18: 원본 메시 치수
A19: 오디오 | B19: 마이크 | C19: MEMS 마이크 모듈 | D19: 1 | E19: 0 | F19: =D19+E19*비교!$C$5 -> 1 | G19: 2000 | H19: KRW | I19: =IF(H19="USD",G19*비교!$C$4,G19) -> 2000 | J19: =F19*I19 -> 2000 | K19: 추정 | L19: 네이버쇼핑 최저가 | M19: https://search.shopping.naver.com/search/all?query=MEMS+%EB%A7%88%EC%9D%B4%ED%81%AC+%EB%AA%A8%EB%93%88&sort=price_asc | N19: 검색
A20: 전원 | B20: 배터리+충전기 | C20: NP-F550 호환 2S 7.2V 배터리 + USB 충전기 세트 | D20: 1 | E20: 1 | F20: =D20+E20*비교!$C$5 -> 2 | G20: 25000 | H20: KRW | I20: =IF(H20="USD",G20*비교!$C$4,G20) -> 25000 | J20: =F20*I20 -> 50000 | K20: 추정 | L20: 네이버쇼핑 최저가 | M20: https://search.shopping.naver.com/search/all?query=NP-F550+%ED%98%B8%ED%99%98+%EB%B0%B0%ED%84%B0%EB%A6%AC+%EC%B6%A9%EC%A0%84%EA%B8%B0+%EC%84%B8%ED%8A%B8&sort=price_asc | N20: 검색 | O20: NEEWER 4개+충전기 ₩163,000(확인): https://kr.neewer.com/products/neewer-4-packs-7-4v-2600mah-np-f550-replacement-batteries-66601510 | P20: 서보에 직결(6.6–8.2 V). 약 1시간 동작. 오리지널 예비 = 배터리 세트 1개 추가
A21: 전원 | B21: 배터리 플레이트 | C21: NP-F 배터리 홀더 (리드선) | D21: 1 | E21: 0 | F21: =D21+E21*비교!$C$5 -> 1 | G21: 4000 | H21: KRW | I21: =IF(H21="USD",G21*비교!$C$4,G21) -> 4000 | J21: =F21*I21 -> 4000 | K21: 추정 | L21: 알리익스프레스 | M21: https://www.aliexpress.com/w/wholesale-NP-F-battery-plate-holder.html?SortType=price_asc | N21: 검색 | O21: 네이버: https://search.shopping.naver.com/search/all?query=NP-F+%EB%B0%B0%ED%84%B0%EB%A6%AC+%ED%94%8C%EB%A0%88%EC%9D%B4%ED%8A%B8&sort=price_asc | P21: 출력물 power_support에 고정
A22: 전원 | B22: 5V 강압 모듈 | C22: MP1584EN 3A | D22: 1 | E22: 1 | F22: =D22+E22*비교!$C$5 -> 2 | G22: 1500 | H22: KRW | I22: =IF(H22="USD",G22*비교!$C$4,G22) -> 1500 | J22: =F22*I22 -> 3000 | K22: 추정 | L22: 네이버쇼핑 최저가 | M22: https://search.shopping.naver.com/search/all?query=MP1584EN+%EA%B0%95%EC%95%95+%EB%AA%A8%EB%93%88&sort=price_asc | N22: 검색 | P22: SBC·센서용. 출력 5.1V로 조정 후 연결
A23: 전원 | B23: 전원 스위치 | C23: 슬라이드/로커 스위치 5 A 이상 | D23: 1 | E23: 0 | F23: =D23+E23*비교!$C$5 -> 1 | G23: 1000 | H23: KRW | I23: =IF(H23="USD",G23*비교!$C$4,G23) -> 1000 | J23: =F23*I23 -> 1000 | K23: 추정 | L23: 네이버쇼핑 최저가 | M23: https://search.shopping.naver.com/search/all?query=%EB%AF%B8%EB%8B%88+%EB%A1%9C%EC%BB%A4%EC%8A%A4%EC%9C%84%EC%B9%98+5A&sort=price_asc | N23: 검색
A24: 전원 | B24: 퓨즈 | C24: 미니 블레이드 퓨즈 5A + 홀더 | D24: 1 | E24: 0 | F24: =D24+E24*비교!$C$5 -> 1 | G24: 1500 | H24: KRW | I24: =IF(H24="USD",G24*비교!$C$4,G24) -> 1500 | J24: =F24*I24 -> 1500 | K24: 추정 | L24: 네이버쇼핑 최저가 | M24: https://search.shopping.naver.com/search/all?query=%EB%AF%B8%EB%8B%88+%EB%B8%94%EB%A0%88%EC%9D%B4%EB%93%9C+%ED%93%A8%EC%A6%88+%ED%99%80%EB%8D%94&sort=price_asc | N24: 검색 | P24: 서보 버스 단락 보호
A25: 전원 | B25: 커넥터 | C25: XT30 수/암 세트 | D25: 2 | E25: 0 | F25: =D25+E25*비교!$C$5 -> 2 | G25: 500 | H25: KRW | I25: =IF(H25="USD",G25*비교!$C$4,G25) -> 500 | J25: =F25*I25 -> 1000 | K25: 추정 | L25: 알리익스프레스 | M25: https://www.aliexpress.com/w/wholesale-XT30-connector.html?SortType=price_asc | N25: 검색 | P25: 저렴한 버전은 배터리 플레이트 리드선 직결
A26: 버스·PCB | B26: 반이중 버퍼 IC | C26: SN74LVC2G241DCUR | D26: 1 | E26: 2 | F26: =D26+E26*비교!$C$5 -> 3 | G26: 0.15 | H26: USD | I26: =IF(H26="USD",G26*비교!$C$4,G26) -> 210 | J26: =F26*I26 -> 630 | K26: 추정 | L26: LCSC | M26: https://www.lcsc.com/search?q=SN74LVC2G241 | N26: 검색 | P26: ROBOTIS 레퍼런스 반이중 회로. 1단계는 변환기판에 납땜
A27: 버스·PCB | B27: 자작 HAT PCB | C27: 65×30 mm 2층 PCB 5장 (배송 포함) | D27: 1 | E27: 0 | F27: =D27+E27*비교!$C$5 -> 1 | G27: 10 | H27: USD | I27: =IF(H27="USD",G27*비교!$C$4,G27) -> 14000 | J27: =F27*I27 -> 14000 | K27: 추정 | L27: JLCPCB | M27: https://jlcpcb.com/ | N27: 사이트 | P27: LCSC 부품과 함께 주문하면 배송 합산. 저렴한 버전은 만능기판으로 대체 가능
A28: 버스·PCB | B28: 다이나믹셀 커넥터 | C28: JST EH 3핀 헤더 (B3B-EH-A) | D28: 6 | E28: 0 | F28: =D28+E28*비교!$C$5 -> 6 | G28: 100 | H28: KRW | I28: =IF(H28="USD",G28*비교!$C$4,G28) -> 100 | J28: =F28*I28 -> 600 | K28: 추정 | L28: 알리익스프레스 | M28: https://www.aliexpress.com/w/wholesale-JST-EH-2.5mm-3pin-header.html?SortType=price_asc | N28: 검색 | P28: 보통 수십 개 묶음
A29: 기구 | B29: 볼베어링 (대) | C29: 16×22×4 mm (SMR2216ZZ) | D29: 11 | E29: 2 | F29: =D29+E29*비교!$C$5 -> 13 | G29: 1200 | H29: KRW | I29: =IF(H29="USD",G29*비교!$C$4,G29) -> 1200 | J29: =F29*I29 -> 15600 | K29: 추정 | L29: 알리익스프레스 | M29: https://www.aliexpress.com/w/wholesale-16x22x4-bearing.html?SortType=price_asc | N29: 검색 | O29: 네이버: https://search.shopping.naver.com/search/all?query=16x22x4+%EB%B2%A0%EC%96%B4%EB%A7%81&sort=price_asc | P29: MJCF 실측. 10개 묶음 2개
A30: 기구 | B30: 볼베어링 (소) | C30: 10×15×3 mm | D30: 3 | E30: 1 | F30: =D30+E30*비교!$C$5 -> 4 | G30: 1000 | H30: KRW | I30: =IF(H30="USD",G30*비교!$C$4,G30) -> 1000 | J30: =F30*I30 -> 4000 | K30: 추정 | L30: 알리익스프레스 | M30: https://www.aliexpress.com/w/wholesale-10x15x3-bearing.html?SortType=price_asc | N30: 검색 | O30: 네이버: https://search.shopping.naver.com/search/all?query=10x15x3+%EB%B2%A0%EC%96%B4%EB%A7%81&sort=price_asc | P30: MJCF 실측
A31: 기구 | B31: 볼트 키트 | C31: M2/M2.5/M3 볼트·너트 키트 | D31: 1 | E31: 0 | F31: =D31+E31*비교!$C$5 -> 1 | G31: 6000 | H31: KRW | I31: =IF(H31="USD",G31*비교!$C$4,G31) -> 6000 | J31: =F31*I31 -> 6000 | K31: 추정 | L31: 알리익스프레스 | M31: https://www.aliexpress.com/w/wholesale-M2-M2.5-M3-screw-kit.html?SortType=price_asc | N31: 검색 | P31: 보유 시 0원. 서보 체결은 동봉 M2 탭볼트
A32: 기구 | B32: 인서트 너트 | C32: M2/M2.5 열압착 인서트 | D32: 1 | E32: 0 | F32: =D32+E32*비교!$C$5 -> 1 | G32: 4000 | H32: KRW | I32: =IF(H32="USD",G32*비교!$C$4,G32) -> 4000 | J32: =F32*I32 -> 4000 | K32: 추정 | L32: 알리익스프레스 | M32: https://www.aliexpress.com/w/wholesale-M2-heat-set-insert.html?SortType=price_asc | N32: 검색 | P32: 저렴한 버전은 탭볼트 직결
A33: 기구 | B33: 판재 4종 (알루미늄) | C33: 레이저 가공: 1 mm ×5장(보강판2·몸통판1·롤판2) + 2 mm ×2장(목판) | D33: 1 | E33: 0 | F33: =D33+E33*비교!$C$5 -> 1 | G33: 40000 | H33: KRW | I33: =IF(H33="USD",G33*비교!$C$4,G33) -> 40000 | J33: =F33*I33 -> 40000 | K33: 추정 | L33: 레이저 가공 업체 | M33: https://search.shopping.naver.com/search/all?query=%EC%95%8C%EB%A3%A8%EB%AF%B8%EB%8A%84+%EB%A0%88%EC%9D%B4%EC%A0%80+%EA%B0%80%EA%B3%B5+%EC%86%8C%EB%9F%89&sort=price_asc | N33: 검색 | O33: JLCCNC 판금: https://jlccnc.com/ / PCBWay: https://www.pcbway.com/ | P33: DXF: cad/plates/dynamixel. 소량 최소주문·배송비 때문에 견적 편차 큼 — 견적 받아 수정
A34: 출력소재 | B34: 경질 필라멘트 | C34: PETG 1 kg | D34: 1 | E34: 0 | F34: =D34+E34*비교!$C$5 -> 1 | G34: 15000 | H34: KRW | I34: =IF(H34="USD",G34*비교!$C$4,G34) -> 15000 | J34: =F34*I34 -> 15000 | K34: 추정 | L34: 네이버쇼핑 최저가 | M34: https://search.shopping.naver.com/search/all?query=PETG+%ED%95%84%EB%9D%BC%EB%A9%98%ED%8A%B8+1kg&sort=price_asc | N34: 검색 | P34: 보유 재고 있으면 0원. 실부피 약 207 cm³
A35: 출력소재 | B35: 연질 필라멘트 | C35: TPU 95A 0.5–1 kg | D35: 1 | E35: 0 | F35: =D35+E35*비교!$C$5 -> 1 | G35: 18000 | H35: KRW | I35: =IF(H35="USD",G35*비교!$C$4,G35) -> 18000 | J35: =F35*I35 -> 18000 | K35: 추정 | L35: 네이버쇼핑 최저가 | M35: https://search.shopping.naver.com/search/all?query=TPU+95A+%ED%95%84%EB%9D%BC%EB%A9%98%ED%8A%B8&sort=price_asc | N35: 검색 | P35: 발바닥·부리 연질부 약 34 cm³
A36: 기타 | B36: 게임패드 | C36: Xbox 무선 컨트롤러 | D36: 1 | E36: 0 | F36: =D36+E36*비교!$C$5 -> 1 | G36: 55000 | H36: KRW | I36: =IF(H36="USD",G36*비교!$C$4,G36) -> 55000 | J36: =F36*I36 -> 55000 | K36: 추정 | L36: 네이버쇼핑 최저가 | M36: https://search.shopping.naver.com/search/all?query=Xbox+%EB%AC%B4%EC%84%A0+%EC%BB%A8%ED%8A%B8%EB%A1%A4%EB%9F%AC&sort=price_asc | N36: 검색 | P36: 원본 기본 조종기. 저렴한 버전은 노트북 UDP 패드(런타임 지원)
I38: 합계 | J38: =SUM(J6:J36) -> 896602
I39: 서보 비중 | J39: =IFERROR(J6/J38,0) -> 0.47111204

Sheet 저렴한 버전
A1: Microduck 클론 BOM — 저렴한 버전
A2: 다이나믹셀 · 걷기에 필요한 것만: 14축(부리 고정), 센서·오디오·게임패드 제외, CP2102로 U2D2 대체, 예비 없음.
A3: 환율·예비 포함 여부는 '비교' 시트의 노란 칸에서 바꾼다. 쿠폰 할인·배송비 미반영.
A5: 분류 | B5: 품목 | C5: 규격/모델 | D5: 수량 | E5: 예비 | F5: 총수량 | G5: 단가 | H5: 통화 | I5: 단가(원) | J5: 합계(원) | K5: 가격근거 | L5: 구매처 | M5: 구매 링크 | N5: 링크유형 | O5: 대안 구매처 | P5: 메모
A6: 구동 | B6: 다이나믹셀 서보 | C6: ROBOTIS XL330-M288-T | D6: 14 | E6: 0 | F6: =D6+E6*비교!$C$5 -> 14 | G6: 26400 | H6: KRW | I6: =IF(H6="USD",G6*비교!$C$4,G6) -> 26400 | J6: =F6*I6 -> 369600 | K6: 확인 | L6: 로보티즈 공식몰 | M6: https://www.robotis.com/shop/item.php?it_id=902-0163-000 | N6: 상품 | O6: 로보몰(동일가, 품절): https://robomall.co.kr/product/%EB%8B%A4%EC%9D%B4%EB%82%98%EB%AF%B9%EC%85%80-xl330-m288-t/21150/ | P6: 준비기간 40일 → 가장 먼저 주문. 5만원 이상 무료배송. 저렴한 버전은 부리(ID 34) 생략 → 14개
A7: 구동 | B7: USB-TTL 변환기 (U2D2 대용) | C7: CP2102 모듈 3.3V | D7: 1 | E7: 0 | F7: =D7+E7*비교!$C$5 -> 1 | G7: 2500 | H7: KRW | I7: =IF(H7="USD",G7*비교!$C$4,G7) -> 2500 | J7: =F7*I7 -> 2500 | K7: 추정 | L7: 네이버쇼핑 최저가 | M7: https://search.shopping.naver.com/search/all?query=CP2102+USB+TTL+%EB%AA%A8%EB%93%88&sort=price_asc | N7: 검색 | P7: SN74LVC2G241 반이중 회로와 함께 서보 ID 설정·벤치 테스트
A8: 컴퓨팅 | B8: 메인 SBC | C8: Radxa Zero 3W (1GB/8GB eMMC 또는 2GB/16GB) | D8: 1 | E8: 0 | F8: =D8+E8*비교!$C$5 -> 1 | G8: 20 | H8: USD | I8: =IF(H8="USD",G8*비교!$C$4,G8) -> 28000 | J8: =F8*I8 -> 28000 | K8: 확인 | L8: ARACE (Radxa 공식 파트너) | M8: https://arace.tech/products/radxa-zero-3w | N8: 상품 | O8: 알리: https://www.aliexpress.com/w/wholesale-Radxa-Zero-3W.html?SortType=price_asc / allnetchina: https://shop.allnetchina.cn/products/copy-of-radxa-zero-3w | P8: ⚠ 2026-10-29 확인 시 ARACE·ameridroid·allnetchina 전 모델 품절. 재입고 알림 신청. 대안: Orange Pi Zero 2W / Pi Zero 2W (같은 65×30, 런타임 포팅 필요)
A9: 컴퓨팅 | B9: 방열판 | C9: Radxa ZERO 3W/3E 전용 히트싱크 | D9: 1 | E9: 0 | F9: =D9+E9*비교!$C$5 -> 1 | G9: 3000 | H9: KRW | I9: =IF(H9="USD",G9*비교!$C$4,G9) -> 3000 | J9: =F9*I9 -> 3000 | K9: 추정 | L9: 알리익스프레스 | M9: https://www.aliexpress.us/item/3256806829446736.html | N9: 상품 | P9: 원본 문서에 95 °C 스로틀링 사례
A10: 컴퓨팅 | B10: microSD | C10: 32GB A1 (eMMC 없는 보드일 때만) | D10: 1 | E10: 0 | F10: =D10+E10*비교!$C$5 -> 1 | G10: 6000 | H10: KRW | I10: =IF(H10="USD",G10*비교!$C$4,G10) -> 6000 | J10: =F10*I10 -> 6000 | K10: 추정 | L10: 네이버쇼핑 최저가 | M10: https://search.shopping.naver.com/search/all?query=microSD+32GB+A1&sort=price_asc | N10: 검색 | P10: eMMC 없는 저가 보드 선택 시. 보유 중이면 0원
A11: 센서 | B11: 몸통 IMU | C11: SparkFun 6DoF LSM6DSV16X (Qwiic) SEN-21325 | D11: 1 | E11: 0 | F11: =D11+E11*비교!$C$5 -> 1 | G11: 24.54 | H11: USD | I11: =IF(H11="USD",G11*비교!$C$4,G11) -> 34356 | J11: =F11*I11 -> 34356 | K11: 확인 | L11: SparkFun | M11: https://www.sparkfun.com/sparkfun-6dof-imu-breakout-lsm6dsv16x-qwiic.html | N11: 상품 | O11: 알리 저가 모듈: https://www.aliexpress.com/w/wholesale-LSM6DSV16X-module.html?SortType=price_asc | P11: 원본과 같은 칩. 알리 저가 모듈을 찾으면 저렴한 버전은 그쪽으로
A12: 센서 | B12: IMU 브리지 MCU | C12: ESP32-C3 SuperMini | D12: 1 | E12: 0 | F12: =D12+E12*비교!$C$5 -> 1 | G12: 3000 | H12: KRW | I12: =IF(H12="USD",G12*비교!$C$4,G12) -> 3000 | J12: =F12*I12 -> 3000 | K12: 추정 | L12: 네이버쇼핑 최저가 | M12: https://search.shopping.naver.com/search/all?query=ESP32-C3+SuperMini&sort=price_asc | N12: 검색 | O12: 알리: https://www.aliexpress.com/w/wholesale-ESP32-C3-SuperMini.html?SortType=price_asc | P12: 버스 ID 200 슬레이브 펌웨어 (firmware/imu_to_dxl)
A13: 전원 | B13: 배터리+충전기 | C13: NP-F550 호환 2S 7.2V 배터리 + USB 충전기 세트 | D13: 1 | E13: 0 | F13: =D13+E13*비교!$C$5 -> 1 | G13: 25000 | H13: KRW | I13: =IF(H13="USD",G13*비교!$C$4,G13) -> 25000 | J13: =F13*I13 -> 25000 | K13: 추정 | L13: 네이버쇼핑 최저가 | M13: https://search.shopping.naver.com/search/all?query=NP-F550+%ED%98%B8%ED%99%98+%EB%B0%B0%ED%84%B0%EB%A6%AC+%EC%B6%A9%EC%A0%84%EA%B8%B0+%EC%84%B8%ED%8A%B8&sort=price_asc | N13: 검색 | O13: NEEWER 4개+충전기 ₩163,000(확인): https://kr.neewer.com/products/neewer-4-packs-7-4v-2600mah-np-f550-replacement-batteries-66601510 | P13: 서보에 직결(6.6–8.2 V). 약 1시간 동작. 오리지널 예비 = 배터리 세트 1개 추가
A14: 전원 | B14: 배터리 플레이트 | C14: NP-F 배터리 홀더 (리드선) | D14: 1 | E14: 0 | F14: =D14+E14*비교!$C$5 -> 1 | G14: 4000 | H14: KRW | I14: =IF(H14="USD",G14*비교!$C$4,G14) -> 4000 | J14: =F14*I14 -> 4000 | K14: 추정 | L14: 알리익스프레스 | M14: https://www.aliexpress.com/w/wholesale-NP-F-battery-plate-holder.html?SortType=price_asc | N14: 검색 | O14: 네이버: https://search.shopping.naver.com/search/all?query=NP-F+%EB%B0%B0%ED%84%B0%EB%A6%AC+%ED%94%8C%EB%A0%88%EC%9D%B4%ED%8A%B8&sort=price_asc | P14: 출력물 power_support에 고정
A15: 전원 | B15: 5V 강압 모듈 | C15: MP1584EN 3A | D15: 1 | E15: 0 | F15: =D15+E15*비교!$C$5 -> 1 | G15: 1500 | H15: KRW | I15: =IF(H15="USD",G15*비교!$C$4,G15) -> 1500 | J15: =F15*I15 -> 1500 | K15: 추정 | L15: 네이버쇼핑 최저가 | M15: https://search.shopping.naver.com/search/all?query=MP1584EN+%EA%B0%95%EC%95%95+%EB%AA%A8%EB%93%88&sort=price_asc | N15: 검색 | P15: SBC·센서용. 출력 5.1V로 조정 후 연결
A16: 전원 | B16: 전원 스위치 | C16: 슬라이드/로커 스위치 5 A 이상 | D16: 1 | E16: 0 | F16: =D16+E16*비교!$C$5 -> 1 | G16: 1000 | H16: KRW | I16: =IF(H16="USD",G16*비교!$C$4,G16) -> 1000 | J16: =F16*I16 -> 1000 | K16: 추정 | L16: 네이버쇼핑 최저가 | M16: https://search.shopping.naver.com/search/all?query=%EB%AF%B8%EB%8B%88+%EB%A1%9C%EC%BB%A4%EC%8A%A4%EC%9C%84%EC%B9%98+5A&sort=price_asc | N16: 검색
A17: 전원 | B17: 퓨즈 | C17: 미니 블레이드 퓨즈 5A + 홀더 | D17: 1 | E17: 0 | F17: =D17+E17*비교!$C$5 -> 1 | G17: 1500 | H17: KRW | I17: =IF(H17="USD",G17*비교!$C$4,G17) -> 1500 | J17: =F17*I17 -> 1500 | K17: 추정 | L17: 네이버쇼핑 최저가 | M17: https://search.shopping.naver.com/search/all?query=%EB%AF%B8%EB%8B%88+%EB%B8%94%EB%A0%88%EC%9D%B4%EB%93%9C+%ED%93%A8%EC%A6%88+%ED%99%80%EB%8D%94&sort=price_asc | N17: 검색 | P17: 서보 버스 단락 보호
A18: 버스·PCB | B18: 반이중 버퍼 IC | C18: SN74LVC2G241DCUR | D18: 1 | E18: 0 | F18: =D18+E18*비교!$C$5 -> 1 | G18: 0.15 | H18: USD | I18: =IF(H18="USD",G18*비교!$C$4,G18) -> 210 | J18: =F18*I18 -> 210 | K18: 추정 | L18: LCSC | M18: https://www.lcsc.com/search?q=SN74LVC2G241 | N18: 검색 | P18: ROBOTIS 레퍼런스 반이중 회로. 1단계는 변환기판에 납땜
A19: 버스·PCB | B19: 자작 HAT PCB | C19: 65×30 mm 2층 PCB 5장 (배송 포함) | D19: 1 | E19: 0 | F19: =D19+E19*비교!$C$5 -> 1 | G19: 10 | H19: USD | I19: =IF(H19="USD",G19*비교!$C$4,G19) -> 14000 | J19: =F19*I19 -> 14000 | K19: 추정 | L19: JLCPCB | M19: https://jlcpcb.com/ | N19: 사이트 | P19: LCSC 부품과 함께 주문하면 배송 합산. 저렴한 버전은 만능기판으로 대체 가능
A20: 버스·PCB | B20: 다이나믹셀 커넥터 | C20: JST EH 3핀 헤더 (B3B-EH-A) | D20: 6 | E20: 0 | F20: =D20+E20*비교!$C$5 -> 6 | G20: 100 | H20: KRW | I20: =IF(H20="USD",G20*비교!$C$4,G20) -> 100 | J20: =F20*I20 -> 600 | K20: 추정 | L20: 알리익스프레스 | M20: https://www.aliexpress.com/w/wholesale-JST-EH-2.5mm-3pin-header.html?SortType=price_asc | N20: 검색 | P20: 보통 수십 개 묶음
A21: 기구 | B21: 볼베어링 (대) | C21: 16×22×4 mm (SMR2216ZZ) | D21: 11 | E21: 0 | F21: =D21+E21*비교!$C$5 -> 11 | G21: 1200 | H21: KRW | I21: =IF(H21="USD",G21*비교!$C$4,G21) -> 1200 | J21: =F21*I21 -> 13200 | K21: 추정 | L21: 알리익스프레스 | M21: https://www.aliexpress.com/w/wholesale-16x22x4-bearing.html?SortType=price_asc | N21: 검색 | O21: 네이버: https://search.shopping.naver.com/search/all?query=16x22x4+%EB%B2%A0%EC%96%B4%EB%A7%81&sort=price_asc | P21: MJCF 실측. 10개 묶음 2개
A22: 기구 | B22: 볼베어링 (소) | C22: 10×15×3 mm | D22: 3 | E22: 0 | F22: =D22+E22*비교!$C$5 -> 3 | G22: 1000 | H22: KRW | I22: =IF(H22="USD",G22*비교!$C$4,G22) -> 1000 | J22: =F22*I22 -> 3000 | K22: 추정 | L22: 알리익스프레스 | M22: https://www.aliexpress.com/w/wholesale-10x15x3-bearing.html?SortType=price_asc | N22: 검색 | O22: 네이버: https://search.shopping.naver.com/search/all?query=10x15x3+%EB%B2%A0%EC%96%B4%EB%A7%81&sort=price_asc | P22: MJCF 실측
A23: 기구 | B23: 볼트 키트 | C23: M2/M2.5/M3 볼트·너트 키트 | D23: 1 | E23: 0 | F23: =D23+E23*비교!$C$5 -> 1 | G23: 6000 | H23: KRW | I23: =IF(H23="USD",G23*비교!$C$4,G23) -> 6000 | J23: =F23*I23 -> 6000 | K23: 추정 | L23: 알리익스프레스 | M23: https://www.aliexpress.com/w/wholesale-M2-M2.5-M3-screw-kit.html?SortType=price_asc | N23: 검색 | P23: 보유 시 0원. 서보 체결은 동봉 M2 탭볼트
A24: 기구 | B24: 판재 3종 (FR4 대체) | C24: PCB 업체 FR4 1.0 mm 외곽 가공 (보강판·몸통판·롤판), 목판은 출력 | D24: 1 | E24: 0 | F24: =D24+E24*비교!$C$5 -> 1 | G24: 8 | H24: USD | I24: =IF(H24="USD",G24*비교!$C$4,G24) -> 11200 | J24: =F24*I24 -> 11200 | K24: 추정 | L24: JLCPCB | M24: https://jlcpcb.com/ | N24: 사이트 | P24: HAT PCB와 같이 주문하면 배송비 합산. 알루미늄보다 강성 낮지만 출력물보다 훨씬 단단
A25: 출력소재 | B25: 경질 필라멘트 | C25: PETG 1 kg | D25: 1 | E25: 0 | F25: =D25+E25*비교!$C$5 -> 1 | G25: 15000 | H25: KRW | I25: =IF(H25="USD",G25*비교!$C$4,G25) -> 15000 | J25: =F25*I25 -> 15000 | K25: 추정 | L25: 네이버쇼핑 최저가 | M25: https://search.shopping.naver.com/search/all?query=PETG+%ED%95%84%EB%9D%BC%EB%A9%98%ED%8A%B8+1kg&sort=price_asc | N25: 검색 | P25: 보유 재고 있으면 0원. 실부피 약 207 cm³
A26: 출력소재 | B26: 연질 필라멘트 | C26: TPU 95A 0.5–1 kg | D26: 1 | E26: 0 | F26: =D26+E26*비교!$C$5 -> 1 | G26: 18000 | H26: KRW | I26: =IF(H26="USD",G26*비교!$C$4,G26) -> 18000 | J26: =F26*I26 -> 18000 | K26: 추정 | L26: 네이버쇼핑 최저가 | M26: https://search.shopping.naver.com/search/all?query=TPU+95A+%ED%95%84%EB%9D%BC%EB%A9%98%ED%8A%B8&sort=price_asc | N26: 검색 | P26: 발바닥·부리 연질부 약 34 cm³
I28: 합계 | J28: =SUM(J6:J26) -> 560666
I29: 서보 비중 | J29: =IFERROR(J6/J28,0) -> 0.659216

Sheet 일반 서보 버전
A1: Microduck 클론 BOM — 일반 서보 버전
A2: MG996R ×11 + MG90S ×4, 1.5배 확대, Raspberry Pi + PCA9685 + ADS1115 위치 피드백 개조. plan-hobby-servo.md 참고.
A3: 환율·예비 포함 여부는 '비교' 시트의 노란 칸에서 바꾼다. 쿠폰 할인·배송비 미반영.
A5: 분류 | B5: 품목 | C5: 규격/모델 | D5: 수량 | E5: 예비 | F5: 총수량 | G5: 단가 | H5: 통화 | I5: 단가(원) | J5: 합계(원) | K5: 가격근거 | L5: 구매처 | M5: 구매 링크 | N5: 링크유형 | O5: 대안 구매처 | P5: 메모
A6: 구동 | B6: 다리·목 서보 | C6: MG996R 메탈기어 (TowerPro 호환) | D6: 11 | E6: 2 | F6: =D6+E6*비교!$C$5 -> 13 | G6: 5000 | H6: KRW | I6: =IF(H6="USD",G6*비교!$C$4,G6) -> 5000 | J6: =F6*I6 -> 65000 | K6: 추정 | L6: 디바이스마트 | M6: https://www.devicemart.co.kr/goods/view?no=1313388 | N6: 상품 | O6: 네이버: https://search.shopping.naver.com/search/all?query=MG996R+%EC%84%9C%EB%B3%B4%EB%AA%A8%ED%84%B0&sort=price_asc / 알리: https://www.aliexpress.com/w/wholesale-MG996R-servo.html?SortType=price_asc | P6: 다리 10 + neck_pitch 1. 9.4 kgf·cm@4.8V, 11 kgf·cm@6V, 55 g. 호환품 편차 커서 예비 2개
A7: 구동 | B7: 머리·부리 서보 | C7: MG90S 메탈기어 | D7: 4 | E7: 1 | F7: =D7+E7*비교!$C$5 -> 5 | G7: 3000 | H7: KRW | I7: =IF(H7="USD",G7*비교!$C$4,G7) -> 3000 | J7: =F7*I7 -> 15000 | K7: 추정 | L7: 네이버쇼핑 최저가 | M7: https://search.shopping.naver.com/search/all?query=MG90S+%EC%84%9C%EB%B3%B4%EB%AA%A8%ED%84%B0&sort=price_asc | N7: 검색 | O7: 알리: https://www.aliexpress.com/w/wholesale-MG90S-servo.html?SortType=price_asc | P7: head_pitch·yaw·roll + 부리. 2.2 kgf·cm@6V, 13.4 g. SG90(플라스틱 기어)은 낙하에 약함
A8: 구동 | B8: 알루미늄 서보 혼 | C8: 25T 알루미늄 원형 혼 (MG996R용) | D8: 11 | E8: 0 | F8: =D8+E8*비교!$C$5 -> 11 | G8: 1500 | H8: KRW | I8: =IF(H8="USD",G8*비교!$C$4,G8) -> 1500 | J8: =F8*I8 -> 16500 | K8: 추정 | L8: 알리익스프레스 | M8: https://www.aliexpress.com/w/wholesale-25T-aluminum-servo-horn.html?SortType=price_asc | N8: 검색 | P8: 동봉 플라스틱 혼은 하중에 약함
A9: 구동 | B9: 서보 연장선 | C9: 서보 연장 케이블 15–30 cm | D9: 15 | E9: 0 | F9: =D9+E9*비교!$C$5 -> 15 | G9: 300 | H9: KRW | I9: =IF(H9="USD",G9*비교!$C$4,G9) -> 300 | J9: =F9*I9 -> 4500 | K9: 추정 | L9: 알리익스프레스 | M9: https://www.aliexpress.com/w/wholesale-servo-extension-cable-30cm.html?SortType=price_asc | N9: 검색 | P9: 다리 끝 서보용
A10: 컴퓨팅 | B10: 메인 컴퓨터 | C10: Raspberry Pi Zero 2 W (헤더 포함) | D10: 1 | E10: 0 | F10: =D10+E10*비교!$C$5 -> 1 | G10: 30300 | H10: KRW | I10: =IF(H10="USD",G10*비교!$C$4,G10) -> 30300 | J10: =F10*I10 -> 30300 | K10: 확인 | L10: 에듀이노 | M10: https://eduino.kr/product/라즈베리파이-제로-2-w-raspberry-pi-zero-2-w/2949/{$url} | N10: 상품 | O10: 네이버: https://search.shopping.naver.com/search/all?query=%EB%9D%BC%EC%A6%88%EB%B2%A0%EB%A6%AC%ED%8C%8C%EC%9D%B4+%EC%A0%9C%EB%A1%9C+2W&sort=price_asc | P10: ⚠ 2026-10-29 에듀이노 품절. 대안 Pi 4 1–2GB (1.5배 몸통에 들어감)
A11: 컴퓨팅 | B11: microSD | C11: 32GB A1 | D11: 1 | E11: 0 | F11: =D11+E11*비교!$C$5 -> 1 | G11: 6000 | H11: KRW | I11: =IF(H11="USD",G11*비교!$C$4,G11) -> 6000 | J11: =F11*I11 -> 6000 | K11: 추정 | L11: 네이버쇼핑 최저가 | M11: https://search.shopping.naver.com/search/all?query=microSD+32GB+A1&sort=price_asc | N11: 검색
A12: 센서 | B12: IMU | C12: BNO085 모듈 (게임 회전 벡터) | D12: 1 | E12: 0 | F12: =D12+E12*비교!$C$5 -> 1 | G12: 12000 | H12: KRW | I12: =IF(H12="USD",G12*비교!$C$4,G12) -> 12000 | J12: =F12*I12 -> 12000 | K12: 추정 | L12: 알리익스프레스 | M12: https://www.aliexpress.com/w/wholesale-BNO085-module.html?SortType=price_asc | N12: 검색 | O12: BNO055(Open Duck 사용): https://www.aliexpress.com/w/wholesale-BNO055-module.html?SortType=price_asc | P12: 쿼터니언+자이로를 칩이 계산
A13: 센서 | B13: 위치 피드백 ADC | C13: ADS1115 16비트 4채널 모듈 | D13: 4 | E13: 1 | F13: =D13+E13*비교!$C$5 -> 5 | G13: 3000 | H13: KRW | I13: =IF(H13="USD",G13*비교!$C$4,G13) -> 3000 | J13: =F13*I13 -> 15000 | K13: 추정 | L13: 네이버쇼핑 최저가 | M13: https://search.shopping.naver.com/search/all?query=ADS1115+%EB%AA%A8%EB%93%88&sort=price_asc | N13: 검색 | O13: 알리: https://www.aliexpress.com/w/wholesale-ADS1115-module.html?SortType=price_asc | P13: 4개 × 4ch = 16ch, 주소 0x48–0x4B
A14: 센서 | B14: 피드백 배선 | C14: AWG30 랩핑 와이어 + 분압 저항 10kΩ 키트 | D14: 1 | E14: 0 | F14: =D14+E14*비교!$C$5 -> 1 | G14: 5000 | H14: KRW | I14: =IF(H14="USD",G14*비교!$C$4,G14) -> 5000 | J14: =F14*I14 -> 5000 | K14: 추정 | L14: 네이버쇼핑 최저가 | M14: https://search.shopping.naver.com/search/all?query=AWG30+%EB%9E%A9%ED%95%91+%EC%99%80%EC%9D%B4%EC%96%B4&sort=price_asc | N14: 검색 | P14: 서보 가변저항 와이퍼 배선 개조용
A15: 제어·배선 | B15: PWM 드라이버 | C15: PCA9685 16채널 서보 드라이버 | D15: 1 | E15: 0 | F15: =D15+E15*비교!$C$5 -> 1 | G15: 4000 | H15: KRW | I15: =IF(H15="USD",G15*비교!$C$4,G15) -> 4000 | J15: =F15*I15 -> 4000 | K15: 추정 | L15: 네이버쇼핑 최저가 | M15: https://search.shopping.naver.com/search/all?query=PCA9685+%EC%84%9C%EB%B3%B4+%EB%93%9C%EB%9D%BC%EC%9D%B4%EB%B2%84&sort=price_asc | N15: 검색 | O15: 알리: https://www.aliexpress.com/w/wholesale-PCA9685-servo-driver.html?SortType=price_asc | P15: I²C, 하드웨어 PWM
A16: 제어·배선 | B16: 만능기판·헤더 | C16: 만능기판 + 핀헤더 + 전선 | D16: 1 | E16: 0 | F16: =D16+E16*비교!$C$5 -> 1 | G16: 5000 | H16: KRW | I16: =IF(H16="USD",G16*비교!$C$4,G16) -> 5000 | J16: =F16*I16 -> 5000 | K16: 추정 | L16: 네이버쇼핑 최저가 | M16: https://search.shopping.naver.com/search/all?query=%EB%A7%8C%EB%8A%A5%EA%B8%B0%ED%8C%90+%EC%96%91%EB%A9%B4&sort=price_asc | N16: 검색 | P16: 전원 분배·ADC 배선판
A17: 전원 | B17: 배터리 | C17: 2S LiPo 7.4V 2200mAh (XT60) | D17: 1 | E17: 0 | F17: =D17+E17*비교!$C$5 -> 1 | G17: 20000 | H17: KRW | I17: =IF(H17="USD",G17*비교!$C$4,G17) -> 20000 | J17: =F17*I17 -> 20000 | K17: 추정 | L17: 네이버쇼핑 최저가 | M17: https://search.shopping.naver.com/search/all?query=2S+%EB%A6%AC%ED%8F%AC+2200mAh&sort=price_asc | N17: 검색 | P17: 대안: 2S LiFePO4(최대 7.2V)는 MG996R 직결 가능
A18: 전원 | B18: 충전기 | C18: 2S/3S 밸런스 충전기 | D18: 1 | E18: 0 | F18: =D18+E18*비교!$C$5 -> 1 | G18: 10000 | H18: KRW | I18: =IF(H18="USD",G18*비교!$C$4,G18) -> 10000 | J18: =F18*I18 -> 10000 | K18: 추정 | L18: 네이버쇼핑 최저가 | M18: https://search.shopping.naver.com/search/all?query=%EB%A6%AC%ED%8F%AC+%EB%B0%B8%EB%9F%B0%EC%8A%A4+%EC%B6%A9%EC%A0%84%EA%B8%B0+2S+3S&sort=price_asc | N18: 검색 | P18: 보유 시 0원
A19: 전원 | B19: 서보 전원 | C19: 6V 10A 이상 UBEC | D19: 1 | E19: 0 | F19: =D19+E19*비교!$C$5 -> 1 | G19: 12000 | H19: KRW | I19: =IF(H19="USD",G19*비교!$C$4,G19) -> 12000 | J19: =F19*I19 -> 12000 | K19: 추정 | L19: 네이버쇼핑 최저가 | M19: https://search.shopping.naver.com/search/all?query=UBEC+6V+10A&sort=price_asc | N19: 검색 | P19: MG996R 정지전류 2.5A@6V × 11 → 여유 필요
A20: 전원 | B20: 머리 서보·Pi 전원 | C20: MP1584EN 3A 강압 모듈 | D20: 2 | E20: 0 | F20: =D20+E20*비교!$C$5 -> 2 | G20: 1500 | H20: KRW | I20: =IF(H20="USD",G20*비교!$C$4,G20) -> 1500 | J20: =F20*I20 -> 3000 | K20: 추정 | L20: 네이버쇼핑 최저가 | M20: https://search.shopping.naver.com/search/all?query=MP1584EN+%EA%B0%95%EC%95%95+%EB%AA%A8%EB%93%88&sort=price_asc | N20: 검색 | P20: Pi 5.1V 1개, MG90S 5–6V 1개 (서보 레일과 분리)
A21: 전원 | B21: 전해 커패시터 | C21: 2200µF 16V | D21: 2 | E21: 0 | F21: =D21+E21*비교!$C$5 -> 2 | G21: 500 | H21: KRW | I21: =IF(H21="USD",G21*비교!$C$4,G21) -> 500 | J21: =F21*I21 -> 1000 | K21: 추정 | L21: 네이버쇼핑 최저가 | M21: https://search.shopping.naver.com/search/all?query=2200uF+16V+%EC%BD%98%EB%8D%B4%EC%84%9C&sort=price_asc | N21: 검색 | P21: 서보 레일 전압 강하 완화
A22: 전원 | B22: 스위치·퓨즈·커넥터 | C22: 로커스위치 10A, 블레이드 퓨즈 15A+홀더, XT60 | D22: 1 | E22: 0 | F22: =D22+E22*비교!$C$5 -> 1 | G22: 4000 | H22: KRW | I22: =IF(H22="USD",G22*비교!$C$4,G22) -> 4000 | J22: =F22*I22 -> 4000 | K22: 추정 | L22: 네이버쇼핑 최저가 | M22: https://search.shopping.naver.com/search/all?query=%EB%B8%94%EB%A0%88%EC%9D%B4%EB%93%9C+%ED%93%A8%EC%A6%88+%ED%99%80%EB%8D%94+15A&sort=price_asc | N22: 검색
A23: 기구 | B23: 관절 지지 베어링 | C23: 623ZZ 3×10×4 mm | D23: 16 | E23: 4 | F23: =D23+E23*비교!$C$5 -> 20 | G23: 300 | H23: KRW | I23: =IF(H23="USD",G23*비교!$C$4,G23) -> 300 | J23: =F23*I23 -> 6000 | K23: 추정 | L23: 알리익스프레스 | M23: https://www.aliexpress.com/w/wholesale-623ZZ-bearing.html?SortType=price_asc | N23: 검색 | O23: 네이버: https://search.shopping.naver.com/search/all?query=623ZZ+%EB%B2%A0%EC%96%B4%EB%A7%81&sort=price_asc | P23: 서보 반대편 축 지지
A24: 기구 | B24: 볼트 키트 | C24: M2/M3 볼트·너트·인서트 키트 | D24: 1 | E24: 0 | F24: =D24+E24*비교!$C$5 -> 1 | G24: 8000 | H24: KRW | I24: =IF(H24="USD",G24*비교!$C$4,G24) -> 8000 | J24: =F24*I24 -> 8000 | K24: 추정 | L24: 알리익스프레스 | M24: https://www.aliexpress.com/w/wholesale-M3-screw-kit-heat-insert.html?SortType=price_asc | N24: 검색 | P24: 보유 시 0원
A25: 출력소재 | B25: 경질 필라멘트 | C25: PETG 1 kg | D25: 1 | E25: 0 | F25: =D25+E25*비교!$C$5 -> 1 | G25: 15000 | H25: KRW | I25: =IF(H25="USD",G25*비교!$C$4,G25) -> 15000 | J25: =F25*I25 -> 15000 | K25: 추정 | L25: 네이버쇼핑 최저가 | M25: https://search.shopping.naver.com/search/all?query=PETG+%ED%95%84%EB%9D%BC%EB%A9%98%ED%8A%B8+1kg&sort=price_asc | N25: 검색 | P25: 1.5배 확대로 부피 약 3배 → 1 kg 거의 다 사용
A26: 출력소재 | B26: 연질 필라멘트 | C26: TPU 95A 0.5 kg | D26: 1 | E26: 0 | F26: =D26+E26*비교!$C$5 -> 1 | G26: 18000 | H26: KRW | I26: =IF(H26="USD",G26*비교!$C$4,G26) -> 18000 | J26: =F26*I26 -> 18000 | K26: 추정 | L26: 네이버쇼핑 최저가 | M26: https://search.shopping.naver.com/search/all?query=TPU+95A+%ED%95%84%EB%9D%BC%EB%A9%98%ED%8A%B8&sort=price_asc | N26: 검색 | P26: 발바닥
I28: 합계 | J28: =SUM(J6:J26) -> 275300
I29: 서보 비중 | J29: =IFERROR(J6/J28,0) -> 0.23610607

Sheet 출력·부품 치수
A1: part | B1: 분류 | C1: 수량 | D1: X_mm | E1: Y_mm | F1: Z_mm | G1: 부피_cm3 | H1: 권장재질/품목 | I1: 메모 | J1: 파일
A2: ankle_l_v1 | B2: 출력(경질) | C2: 1 | D2: 39.5 | E2: 46.5 | F2: 25.4 | G2: 6.69 | H2: PETG 또는 PLA+ | I2: 롤러 장착용 발목 변형 롤러 옵션 | J2: assets/ankle_l_v1.stl
A3: ankle_left | B3: 출력(경질) | C3: 1 | D3: 39.5 | E3: 36.5 | F3: 25.5 | G3: 7.88 | H3: PETG 또는 PLA+ | J3: assets/ankle_left.stl
A4: ankle_r_v1 | B4: 출력(경질) | C4: 1 | D4: 39.5 | E4: 46.5 | F4: 25.4 | G4: 6.69 | H4: PETG 또는 PLA+ | I4: 롤러 장착용 발목 변형 롤러 옵션 | J4: assets/ankle_r_v1.stl
A5: ankle_right | B5: 출력(경질) | C5: 1 | D5: 39.5 | E5: 36.5 | F5: 25.5 | G5: 7.88 | H5: PETG 또는 PLA+ | J5: assets/ankle_right.stl
A6: banana_pcb_locker | B6: 출력(경질) | C6: 1 | D6: 54.1 | E6: 3.8 | F6: 6.7 | G6: 0.46 | H6: PETG 또는 PLA+ | J6: assets/banana_pcb_locker.stl
A7: bearing_roll | B7: 판재 | C7: 2 | D7: 23 | E7: 3 | F7: 40 | G7: 0.63 | H7: 알루미늄 1 mm | I7: 고관절 롤 베어링판 (+보스 2개 생략) — DXF: cad/plates/dynamixel | J7: assets/bearing_roll.stl
A8: bottom_head_shell | B8: 출력(경질) | C8: 1 | D8: 91.8 | E8: 116.7 | F8: 20.1 | G8: 23.8 | H8: PETG 또는 PLA+ | J8: assets/bottom_head_shell.stl
A9: elec_rpi_robot_hat_pcb | B9: 자작 PCB | C9: 1 | D9: 65 | E9: 30 | F9: 0.8 | G9: 1.57 | H9: 65×30 HAT | I9: 반이중 버스·전원·오디오 등 (직접 설계) | J9: assets/elec_rpi_robot_hat_pcb.stl
A10: face_part | B10: 출력(경질) | C10: 1 | D10: 87.7 | E10: 12.5 | F10: 44.6 | G10: 5.82 | H10: PETG 또는 PLA+ | J10: assets/face_part.stl
A11: foot_left | B11: 출력(경질) | C11: 1 | D11: 40.1 | E11: 54 | F11: 16.9 | G11: 12.18 | H11: PETG 또는 PLA+ | J11: assets/foot_left.stl
A12: foot_right | B12: 출력(경질) | C12: 1 | D12: 40.1 | E12: 54 | F12: 16.9 | G12: 12.18 | H12: PETG 또는 PLA+ | J12: assets/foot_right.stl
A13: hip_l | B13: 출력(경질) | C13: 2 | D13: 32.5 | E13: 34.5 | F13: 19 | G13: 4.52 | H13: PETG 또는 PLA+ | J13: assets/hip_l.stl
A14: jaw | B14: 출력(경질) | C14: 1 | D14: 91.4 | E14: 68.7 | F14: 29.4 | G14: 9.36 | H14: PETG 또는 PLA+ | J14: assets/jaw.stl
A15: jaw_soft | B15: 출력(연질) | C15: 1 | D15: 87.7 | E15: 32.2 | F15: 8.4 | G15: 18.6 | H15: TPU 95A | I15: 부리 아래 연질부 | J15: assets/jaw_soft.stl
A16: left_shell | B16: 출력(경질) | C16: 1 | D16: 33.7 | E16: 80.9 | F16: 41.7 | G16: 11.39 | H16: PETG 또는 PLA+ | J16: assets/left_shell.stl
A17: leg | B17: 출력(경질) | C17: 2 | D17: 8 | E17: 20 | F17: 58 | G17: 3.41 | H17: PETG 또는 PLA+ | J17: assets/leg.stl
A18: lens | B18: 구매품 | C18: 1 | D18: 16.9 | E18: 18.9 | F18: 16.9 | G18: 2.8 | H18: M12 광각 렌즈 | I18: IMX219 카메라용 | J18: assets/lens.stl
A19: m12_lens_holder | B19: 출력(경질) | C19: 1 | D19: 24 | E19: 14.8 | F19: 16 | G19: 1.1 | H19: PETG 또는 PLA+ | J19: assets/m12_lens_holder.stl
A20: motor_support | B20: 출력(경질) | C20: 1 | D20: 73.5 | E20: 54.2 | F20: 18.8 | G20: 7.52 | H20: PETG 또는 PLA+ | J20: assets/motor_support.stl
A21: neck | B21: 판재 | C21: 2 | D21: 2 | E21: 20 | F21: 11 | G21: 0.4 | H21: 알루미늄 2 mm | I21: 목 연결판 — DXF: cad/plates/dynamixel | J21: assets/neck.stl
A22: neck_pitch | B22: 출력(경질) | C22: 1 | D22: 35 | E22: 18 | F22: 27.7 | G22: 4.11 | H22: PETG 또는 PLA+ | J22: assets/neck_pitch.stl
A23: noenoeil | B23: 출력(경질) | C23: 1 | D23: 30 | E23: 9.5 | F23: 30 | G23: 4.25 | H23: PETG 또는 PLA+ | J23: assets/noenoeil.stl
A24: np_f970 | B24: 구매품 | C24: 1 | D24: 38.6 | E24: 20.6 | F24: 70.8 | G24: 51.56 | H24: Sony NP-F 계열 배터리 외형 | I24: 모델은 NP-F970 크기, 실물은 NP-F550 | J24: assets/np_f970.stl
A25: pcb__raspberry_pi_zero_2_w | B25: 구매품 | C25: 1 | D25: 65 | E25: 1.6 | F25: 30 | G25: 3.02 | H25: Radxa Zero 3W (동일 65×30 폼팩터) | I25: 모델은 Pi Zero 2W 자리표시자 | J25: assets/pcb__raspberry_pi_zero_2_w.stl
A26: power_support | B26: 출력(경질) | C26: 1 | D26: 54.5 | E26: 17 | F26: 83.5 | G26: 10.49 | H26: PETG 또는 PLA+ | J26: assets/power_support.stl
A27: right_shell | B27: 출력(경질) | C27: 1 | D27: 31.8 | E27: 80.9 | F27: 41.7 | G27: 11.22 | H27: PETG 또는 PLA+ | J27: assets/right_shell.stl
A28: rim | B28: 출력(경질) | C28: 4 | D28: 7.6 | E28: 20.2 | F28: 20.2 | G28: 1.03 | H28: PETG 또는 PLA+ | I28: 롤러 옵션 | J28: assets/rim.stl
A29: roller_blade | B29: 출력(경질) | C29: 2 | D29: 40.5 | E29: 73 | F29: 30.4 | G29: 11.81 | H29: PETG 또는 PLA+ | I29: 롤러 옵션 | J29: assets/roller_blade.stl
A30: seeed_bearing__configuration__22x16x4 | B30: 구매품 | C30: 11 | D30: 22 | E30: 22 | F30: 4 | G30: 0.49 | H30: 볼베어링 16×22×4 | I30: 관절 지지 베어링 | J30: assets/seeed_bearing__configuration__22x16x4.stl
A31: seeed_bearing__configuration_default | B31: 구매품 | C31: 3 | D31: 15 | E31: 15 | F31: 3 | G31: 0.19 | H31: 볼베어링 10×15×3 | I31: 소형 베어링 | J31: assets/seeed_bearing__configuration_default.stl
A32: soft_mouth_top | B32: 출력(연질) | C32: 1 | D32: 87.8 | E32: 32.6 | F32: 3.3 | G32: 2.7 | H32: TPU 95A | I32: 부리 위 연질부 | J32: assets/soft_mouth_top.stl
A33: sole_left | B33: 출력(연질) | C33: 1 | D33: 41.1 | E33: 54 | F33: 12.9 | G33: 6.25 | H33: TPU 95A | I33: 발바닥 | J33: assets/sole_left.stl
A34: sole_right | B34: 출력(연질) | C34: 1 | D34: 41.1 | E34: 54 | F34: 12.9 | G34: 6.25 | H34: TPU 95A | I34: 발바닥 | J34: assets/sole_right.stl
A35: speaker | B35: 구매품 | C35: 1 | D35: 35 | E35: 25 | F35: 7 | G35: 6.13 | H35: 35×25×7 mm 소형 스피커 | J35: assets/speaker.stl
A36: tire | B36: 출력(연질) | C36: 4 | D36: 7.6 | E36: 30 | F36: 30 | G36: 2.81 | H36: TPU 95A | I36: 롤러 타이어 (선택) 롤러 옵션 | J36: assets/tire.stl
A37: top_head_shell | B37: 출력(경질) | C37: 1 | D37: 91.8 | E37: 122.7 | F37: 46.3 | G37: 29.87 | H37: PETG 또는 PLA+ | J37: assets/top_head_shell.stl
A38: trunk_base | B38: 판재 | C38: 1 | D38: 57 | E38: 36 | F38: 3 | G38: 1.42 | H38: 알루미늄 1 mm | I38: 몸통 바닥판 (+높이 2 mm 보스 4개는 생략) — DXF: cad/plates/dynamixel | J38: assets/trunk_base.stl
A39: upper_leg_left | B39: 출력(경질) | C39: 1 | D39: 28 | E39: 47.7 | F39: 61 | G39: 4.15 | H39: PETG 또는 PLA+ | J39: assets/upper_leg_left.stl
A40: upper_leg_right | B40: 출력(경질) | C40: 1 | D40: 28 | E40: 47.7 | F40: 61 | G40: 4.15 | H40: PETG 또는 PLA+ | J40: assets/upper_leg_right.stl
...
